2025-08-14 21:19:42,162 | INFO | Папка не выбрана. Программа завершена.
2025-08-14 21:21:54,118 | INFO | Выбрана папка: D:\апап
2025-08-14 21:21:54,511 | INFO | Найдено изображений: 3. Начинаем сжатие…
2025-08-14 21:21:54,669 | INFO | Отправляем альбом 1/1 (файлов: 3)…
2025-08-14 21:21:55,966 | INFO | HTTP Request: POST https://api.telegram.org/bot8307958255:AAHOXk2JP0_j-lBh8Xf48lRX180J7GKRMpQ/sendMediaGroup "HTTP/1.1 200 OK"
2025-08-14 21:21:55,968 | INFO | ✅ Альбом 1/1 отправлен. Всего отправлено: 3
2025-08-14 21:21:58,983 | INFO | Готово! Отправлено изображений: 3
2025-08-14 22:03:56,900 | INFO | Выбрана папка: D:\апап
2025-08-14 22:03:57,305 | INFO | Найдено изображений: 3. Начинаем сжатие...
2025-08-14 22:03:57,465 | INFO | Отправляем альбом 1/1...
2025-08-14 22:04:00,192 | INFO | HTTP Request: POST https://api.telegram.org/bot8307958255:AAHOXk2JP0_j-lBh8Xf48lRX180J7GKRMpQ/sendMediaGroup "HTTP/1.1 200 OK"
2025-08-14 22:14:48,348 | INFO | Выбрана папка: D:\апап
2025-08-14 22:14:48,751 | INFO | Найдено изображений: 8. Начинаем сжатие...
2025-08-14 22:14:49,077 | INFO | Отправляем альбом 1/1...
2025-08-14 22:14:56,098 | INFO | HTTP Request: POST https://api.telegram.org/bot8307958255:AAHOXk2JP0_j-lBh8Xf48lRX180J7GKRMpQ/sendMediaGroup "HTTP/1.1 200 OK"
2025-08-14 22:22:10,859 | INFO | HTTP Request: POST https://api.telegram.org/bot8307958255:AAHOXk2JP0_j-lBh8Xf48lRX180J7GKRMpQ/sendMediaGroup "HTTP/1.1 200 OK"
2025-08-14 22:29:11,133 | INFO | HTTP Request: POST https://api.telegram.org/bot8307958255:AAHOXk2JP0_j-lBh8Xf48lRX180J7GKRMpQ/sendMediaGroup "HTTP/1.1 200 OK"
2025-08-14 22:46:17,510 | INFO | HTTP Request: POST https://api.telegram.org/bot8307958255:AAHOXk2JP0_j-lBh8Xf48lRX180J7GKRMpQ/sendMediaGroup "HTTP/1.1 200 OK"
2025-08-14 22:46:49,645 | INFO | HTTP Request: POST https://api.telegram.org/bot8307958255:AAHOXk2JP0_j-lBh8Xf48lRX180J7GKRMpQ/sendMediaGroup "HTTP/1.1 200 OK"
2025-08-14 22:46:57,256 | INFO | HTTP Request: POST https://api.telegram.org/bot8307958255:AAHOXk2JP0_j-lBh8Xf48lRX180J7GKRMpQ/sendMediaGroup "HTTP/1.1 200 OK"
2025-08-14 23:01:33,597 | INFO | HTTP Request: POST https://api.telegram.org/bot8307958255:AAHOXk2JP0_j-lBh8Xf48lRX180J7GKRMpQ/sendMediaGroup "HTTP/1.1 200 OK"
2025-08-14 23:02:06,215 | INFO | HTTP Request: POST https://api.telegram.org/bot8307958255:AAHOXk2JP0_j-lBh8Xf48lRX180J7GKRMpQ/sendMediaGroup "HTTP/1.1 200 OK"
2025-08-14 23:03:07,901 | ERROR | Ошибка при сжатии D:\апап\photo_2025-08-14_16-14-57 (14) — копия — копия.jpg: [Errno 2] No such file or directory: '.compressed_tmp\\photo_2025-08-14_16-14-57 (14) — копия — копия.jpg'
Traceback (most recent call last):
  File "C:\Programms\JABot\upload_bot.py", line 55, in compress_image
    img.save(dst, format="JPEG", optimize=True, quality=75, progressive=True)
    ~~~~~~~~^^^^^^^^^^^^^^^^^^^^^^^^^^^^^^^^^^^^^^^^^^^^^^^^^^^^^^^^^^^^^^^^^
  File "C:\Programms\JABot\.venv\Lib\site-packages\PIL\Image.py", line 2583, in save
    fp = builtins.open(filename, "w+b")
FileNotFoundError: [Errno 2] No such file or directory: '.compressed_tmp\\photo_2025-08-14_16-14-57 (14) — копия — копия.jpg'
2025-08-14 23:03:07,911 | ERROR | Ошибка при сжатии D:\апап\photo_2025-08-14_16-14-57 (14) — копия.jpg: [Errno 2] No such file or directory: '.compressed_tmp\\photo_2025-08-14_16-14-57 (14) — копия.jpg'
Traceback (most recent call last):
  File "C:\Programms\JABot\upload_bot.py", line 55, in compress_image
    img.save(dst, format="JPEG", optimize=True, quality=75, progressive=True)
    ~~~~~~~~^^^^^^^^^^^^^^^^^^^^^^^^^^^^^^^^^^^^^^^^^^^^^^^^^^^^^^^^^^^^^^^^^
  File "C:\Programms\JABot\.venv\Lib\site-packages\PIL\Image.py", line 2583, in save
    fp = builtins.open(filename, "w+b")
FileNotFoundError: [Errno 2] No such file or directory: '.compressed_tmp\\photo_2025-08-14_16-14-57 (14) — копия.jpg'
2025-08-14 23:03:07,929 | ERROR | Ошибка при сжатии D:\апап\photo_2025-08-14_16-14-57 (15) — копия — копия.jpg: [Errno 2] No such file or directory: '.compressed_tmp\\photo_2025-08-14_16-14-57 (15) — копия — копия.jpg'
Traceback (most recent call last):
  File "C:\Programms\JABot\upload_bot.py", line 55, in compress_image
    img.save(dst, format="JPEG", optimize=True, quality=75, progressive=True)
    ~~~~~~~~^^^^^^^^^^^^^^^^^^^^^^^^^^^^^^^^^^^^^^^^^^^^^^^^^^^^^^^^^^^^^^^^^
  File "C:\Programms\JABot\.venv\Lib\site-packages\PIL\Image.py", line 2583, in save
    fp = builtins.open(filename, "w+b")
FileNotFoundError: [Errno 2] No such file or directory: '.compressed_tmp\\photo_2025-08-14_16-14-57 (15) — копия — копия.jpg'
2025-08-14 23:03:07,946 | ERROR | Ошибка при сжатии D:\апап\photo_2025-08-14_16-14-57 (15) — копия.jpg: [Errno 2] No such file or directory: '.compressed_tmp\\photo_2025-08-14_16-14-57 (15) — копия.jpg'
Traceback (most recent call last):
  File "C:\Programms\JABot\upload_bot.py", line 55, in compress_image
    img.save(dst, format="JPEG", optimize=True, quality=75, progressive=True)
    ~~~~~~~~^^^^^^^^^^^^^^^^^^^^^^^^^^^^^^^^^^^^^^^^^^^^^^^^^^^^^^^^^^^^^^^^^
  File "C:\Programms\JABot\.venv\Lib\site-packages\PIL\Image.py", line 2583, in save
    fp = builtins.open(filename, "w+b")
FileNotFoundError: [Errno 2] No such file or directory: '.compressed_tmp\\photo_2025-08-14_16-14-57 (15) — копия.jpg'
2025-08-14 23:03:07,954 | ERROR | Ошибка при сжатии D:\апап\photo_2025-08-14_16-14-57 (16) — копия — копия.jpg: [Errno 2] No such file or directory: '.compressed_tmp\\photo_2025-08-14_16-14-57 (16) — копия — копия.jpg'
Traceback (most recent call last):
  File "C:\Programms\JABot\upload_bot.py", line 55, in compress_image
    img.save(dst, format="JPEG", optimize=True, quality=75, progressive=True)
    ~~~~~~~~^^^^^^^^^^^^^^^^^^^^^^^^^^^^^^^^^^^^^^^^^^^^^^^^^^^^^^^^^^^^^^^^^
  File "C:\Programms\JABot\.venv\Lib\site-packages\PIL\Image.py", line 2583, in save
    fp = builtins.open(filename, "w+b")
FileNotFoundError: [Errno 2] No such file or directory: '.compressed_tmp\\photo_2025-08-14_16-14-57 (16) — копия — копия.jpg'
2025-08-14 23:03:07,962 | ERROR | Ошибка при сжатии D:\апап\photo_2025-08-14_16-14-57 (16) — копия.jpg: [Errno 2] No such file or directory: '.compressed_tmp\\photo_2025-08-14_16-14-57 (16) — копия.jpg'
Traceback (most recent call last):
  File "C:\Programms\JABot\upload_bot.py", line 55, in compress_image
    img.save(dst, format="JPEG", optimize=True, quality=75, progressive=True)
    ~~~~~~~~^^^^^^^^^^^^^^^^^^^^^^^^^^^^^^^^^^^^^^^^^^^^^^^^^^^^^^^^^^^^^^^^^
  File "C:\Programms\JABot\.venv\Lib\site-packages\PIL\Image.py", line 2583, in save
    fp = builtins.open(filename, "w+b")
FileNotFoundError: [Errno 2] No such file or directory: '.compressed_tmp\\photo_2025-08-14_16-14-57 (16) — копия.jpg'
2025-08-14 23:03:07,979 | ERROR | Ошибка при сжатии D:\апап\photo_2025-08-14_16-14-57 (17) — копия — копия.jpg: [Errno 2] No such file or directory: '.compressed_tmp\\photo_2025-08-14_16-14-57 (17) — копия — копия.jpg'
Traceback (most recent call last):
  File "C:\Programms\JABot\upload_bot.py", line 55, in compress_image
    img.save(dst, format="JPEG", optimize=True, quality=75, progressive=True)
    ~~~~~~~~^^^^^^^^^^^^^^^^^^^^^^^^^^^^^^^^^^^^^^^^^^^^^^^^^^^^^^^^^^^^^^^^^
  File "C:\Programms\JABot\.venv\Lib\site-packages\PIL\Image.py", line 2583, in save
    fp = builtins.open(filename, "w+b")
FileNotFoundError: [Errno 2] No such file or directory: '.compressed_tmp\\photo_2025-08-14_16-14-57 (17) — копия — копия.jpg'
2025-08-14 23:03:07,997 | ERROR | Ошибка при сжатии D:\апап\photo_2025-08-14_16-14-57 (17) — копия.jpg: [Errno 2] No such file or directory: '.compressed_tmp\\photo_2025-08-14_16-14-57 (17) — копия.jpg'
Traceback (most recent call last):
  File "C:\Programms\JABot\upload_bot.py", line 55, in compress_image
    img.save(dst, format="JPEG", optimize=True, quality=75, progressive=True)
    ~~~~~~~~^^^^^^^^^^^^^^^^^^^^^^^^^^^^^^^^^^^^^^^^^^^^^^^^^^^^^^^^^^^^^^^^^
  File "C:\Programms\JABot\.venv\Lib\site-packages\PIL\Image.py", line 2583, in save
    fp = builtins.open(filename, "w+b")
FileNotFoundError: [Errno 2] No such file or directory: '.compressed_tmp\\photo_2025-08-14_16-14-57 (17) — копия.jpg'
2025-08-14 23:03:08,005 | ERROR | Ошибка при сжатии D:\апап\photo_2025-08-14_16-14-57 (18) — копия — копия.jpg: [Errno 2] No such file or directory: '.compressed_tmp\\photo_2025-08-14_16-14-57 (18) — копия — копия.jpg'
Traceback (most recent call last):
  File "C:\Programms\JABot\upload_bot.py", line 55, in compress_image
    img.save(dst, format="JPEG", optimize=True, quality=75, progressive=True)
    ~~~~~~~~^^^^^^^^^^^^^^^^^^^^^^^^^^^^^^^^^^^^^^^^^^^^^^^^^^^^^^^^^^^^^^^^^
  File "C:\Programms\JABot\.venv\Lib\site-packages\PIL\Image.py", line 2583, in save
    fp = builtins.open(filename, "w+b")
FileNotFoundError: [Errno 2] No such file or directory: '.compressed_tmp\\photo_2025-08-14_16-14-57 (18) — копия — копия.jpg'
2025-08-14 23:03:08,014 | ERROR | Ошибка при сжатии D:\апап\photo_2025-08-14_16-14-57 (18) — копия.jpg: [Errno 2] No such file or directory: '.compressed_tmp\\photo_2025-08-14_16-14-57 (18) — копия.jpg'
Traceback (most recent call last):
  File "C:\Programms\JABot\upload_bot.py", line 55, in compress_image
    img.save(dst, format="JPEG", optimize=True, quality=75, progressive=True)
    ~~~~~~~~^^^^^^^^^^^^^^^^^^^^^^^^^^^^^^^^^^^^^^^^^^^^^^^^^^^^^^^^^^^^^^^^^
  File "C:\Programms\JABot\.venv\Lib\site-packages\PIL\Image.py", line 2583, in save
    fp = builtins.open(filename, "w+b")
FileNotFoundError: [Errno 2] No such file or directory: '.compressed_tmp\\photo_2025-08-14_16-14-57 (18) — копия.jpg'
2025-08-14 23:03:08,031 | ERROR | Ошибка при сжатии D:\апап\photo_2025-08-14_16-14-57 (19) — копия — копия.jpg: [Errno 2] No such file or directory: '.compressed_tmp\\photo_2025-08-14_16-14-57 (19) — копия — копия.jpg'
Traceback (most recent call last):
  File "C:\Programms\JABot\upload_bot.py", line 55, in compress_image
    img.save(dst, format="JPEG", optimize=True, quality=75, progressive=True)
    ~~~~~~~~^^^^^^^^^^^^^^^^^^^^^^^^^^^^^^^^^^^^^^^^^^^^^^^^^^^^^^^^^^^^^^^^^
  File "C:\Programms\JABot\.venv\Lib\site-packages\PIL\Image.py", line 2583, in save
    fp = builtins.open(filename, "w+b")
FileNotFoundError: [Errno 2] No such file or directory: '.compressed_tmp\\photo_2025-08-14_16-14-57 (19) — копия — копия.jpg'
2025-08-14 23:03:08,049 | ERROR | Ошибка при сжатии D:\апап\photo_2025-08-14_16-14-57 (19) — копия.jpg: [Errno 2] No such file or directory: '.compressed_tmp\\photo_2025-08-14_16-14-57 (19) — копия.jpg'
Traceback (most recent call last):
  File "C:\Programms\JABot\upload_bot.py", line 55, in compress_image
    img.save(dst, format="JPEG", optimize=True, quality=75, progressive=True)
    ~~~~~~~~^^^^^^^^^^^^^^^^^^^^^^^^^^^^^^^^^^^^^^^^^^^^^^^^^^^^^^^^^^^^^^^^^
  File "C:\Programms\JABot\.venv\Lib\site-packages\PIL\Image.py", line 2583, in save
    fp = builtins.open(filename, "w+b")
FileNotFoundError: [Errno 2] No such file or directory: '.compressed_tmp\\photo_2025-08-14_16-14-57 (19) — копия.jpg'
2025-08-14 23:03:08,077 | ERROR | Ошибка при сжатии D:\апап\photo_2025-08-14_16-14-57 — копия.jpg: [Errno 2] No such file or directory: '.compressed_tmp\\photo_2025-08-14_16-14-57 — копия.jpg'
Traceback (most recent call last):
  File "C:\Programms\JABot\upload_bot.py", line 55, in compress_image
    img.save(dst, format="JPEG", optimize=True, quality=75, progressive=True)
    ~~~~~~~~^^^^^^^^^^^^^^^^^^^^^^^^^^^^^^^^^^^^^^^^^^^^^^^^^^^^^^^^^^^^^^^^^
  File "C:\Programms\JABot\.venv\Lib\site-packages\PIL\Image.py", line 2583, in save
    fp = builtins.open(filename, "w+b")
FileNotFoundError: [Errno 2] No such file or directory: '.compressed_tmp\\photo_2025-08-14_16-14-57 — копия.jpg'
2025-08-14 23:03:08,104 | ERROR | Ошибка при сжатии D:\апап\photo_2025-08-14_16-14-57.jpg: [Errno 2] No such file or directory: '.compressed_tmp\\photo_2025-08-14_16-14-57.jpg'
Traceback (most recent call last):
  File "C:\Programms\JABot\upload_bot.py", line 55, in compress_image
    img.save(dst, format="JPEG", optimize=True, quality=75, progressive=True)
    ~~~~~~~~^^^^^^^^^^^^^^^^^^^^^^^^^^^^^^^^^^^^^^^^^^^^^^^^^^^^^^^^^^^^^^^^^
  File "C:\Programms\JABot\.venv\Lib\site-packages\PIL\Image.py", line 2583, in save
    fp = builtins.open(filename, "w+b")
FileNotFoundError: [Errno 2] No such file or directory: '.compressed_tmp\\photo_2025-08-14_16-14-57.jpg'
2025-08-14 23:03:08,123 | ERROR | Ошибка при сжатии D:\апап\с — копия.jpg: [Errno 2] No such file or directory: '.compressed_tmp\\с — копия.jpg'
Traceback (most recent call last):
  File "C:\Programms\JABot\upload_bot.py", line 55, in compress_image
    img.save(dst, format="JPEG", optimize=True, quality=75, progressive=True)
    ~~~~~~~~^^^^^^^^^^^^^^^^^^^^^^^^^^^^^^^^^^^^^^^^^^^^^^^^^^^^^^^^^^^^^^^^^
  File "C:\Programms\JABot\.venv\Lib\site-packages\PIL\Image.py", line 2583, in save
    fp = builtins.open(filename, "w+b")
FileNotFoundError: [Errno 2] No such file or directory: '.compressed_tmp\\с — копия.jpg'
2025-08-14 23:03:08,142 | ERROR | Ошибка при сжатии D:\апап\с.jpg: [Errno 2] No such file or directory: '.compressed_tmp\\с.jpg'
Traceback (most recent call last):
  File "C:\Programms\JABot\upload_bot.py", line 55, in compress_image
    img.save(dst, format="JPEG", optimize=True, quality=75, progressive=True)
    ~~~~~~~~^^^^^^^^^^^^^^^^^^^^^^^^^^^^^^^^^^^^^^^^^^^^^^^^^^^^^^^^^^^^^^^^^
  File "C:\Programms\JABot\.venv\Lib\site-packages\PIL\Image.py", line 2583, in save
    fp = builtins.open(filename, "w+b")
FileNotFoundError: [Errno 2] No such file or directory: '.compressed_tmp\\с.jpg'
2025-08-14 23:03:15,955 | ERROR | Ошибка при сжатии D:\апап\photo_2025-08-14_16-14-57 (14) — копия — копия.jpg: [Errno 2] No such file or directory: '.compressed_tmp\\photo_2025-08-14_16-14-57 (14) — копия — копия.jpg'
Traceback (most recent call last):
  File "C:\Programms\JABot\upload_bot.py", line 55, in compress_image
    img.save(dst, format="JPEG", optimize=True, quality=75, progressive=True)
    ~~~~~~~~^^^^^^^^^^^^^^^^^^^^^^^^^^^^^^^^^^^^^^^^^^^^^^^^^^^^^^^^^^^^^^^^^
  File "C:\Programms\JABot\.venv\Lib\site-packages\PIL\Image.py", line 2583, in save
    fp = builtins.open(filename, "w+b")
FileNotFoundError: [Errno 2] No such file or directory: '.compressed_tmp\\photo_2025-08-14_16-14-57 (14) — копия — копия.jpg'
2025-08-14 23:03:15,963 | ERROR | Ошибка при сжатии D:\апап\photo_2025-08-14_16-14-57 (14) — копия.jpg: [Errno 2] No such file or directory: '.compressed_tmp\\photo_2025-08-14_16-14-57 (14) — копия.jpg'
Traceback (most recent call last):
  File "C:\Programms\JABot\upload_bot.py", line 55, in compress_image
    img.save(dst, format="JPEG", optimize=True, quality=75, progressive=True)
    ~~~~~~~~^^^^^^^^^^^^^^^^^^^^^^^^^^^^^^^^^^^^^^^^^^^^^^^^^^^^^^^^^^^^^^^^^
  File "C:\Programms\JABot\.venv\Lib\site-packages\PIL\Image.py", line 2583, in save
    fp = builtins.open(filename, "w+b")
FileNotFoundError: [Errno 2] No such file or directory: '.compressed_tmp\\photo_2025-08-14_16-14-57 (14) — копия.jpg'
2025-08-14 23:03:15,981 | ERROR | Ошибка при сжатии D:\апап\photo_2025-08-14_16-14-57 (15) — копия — копия.jpg: [Errno 2] No such file or directory: '.compressed_tmp\\photo_2025-08-14_16-14-57 (15) — копия — копия.jpg'
Traceback (most recent call last):
  File "C:\Programms\JABot\upload_bot.py", line 55, in compress_image
    img.save(dst, format="JPEG", optimize=True, quality=75, progressive=True)
    ~~~~~~~~^^^^^^^^^^^^^^^^^^^^^^^^^^^^^^^^^^^^^^^^^^^^^^^^^^^^^^^^^^^^^^^^^
  File "C:\Programms\JABot\.venv\Lib\site-packages\PIL\Image.py", line 2583, in save
    fp = builtins.open(filename, "w+b")
FileNotFoundError: [Errno 2] No such file or directory: '.compressed_tmp\\photo_2025-08-14_16-14-57 (15) — копия — копия.jpg'
2025-08-14 23:03:15,998 | ERROR | Ошибка при сжатии D:\апап\photo_2025-08-14_16-14-57 (15) — копия.jpg: [Errno 2] No such file or directory: '.compressed_tmp\\photo_2025-08-14_16-14-57 (15) — копия.jpg'
Traceback (most recent call last):
  File "C:\Programms\JABot\upload_bot.py", line 55, in compress_image
    img.save(dst, format="JPEG", optimize=True, quality=75, progressive=True)
    ~~~~~~~~^^^^^^^^^^^^^^^^^^^^^^^^^^^^^^^^^^^^^^^^^^^^^^^^^^^^^^^^^^^^^^^^^
  File "C:\Programms\JABot\.venv\Lib\site-packages\PIL\Image.py", line 2583, in save
    fp = builtins.open(filename, "w+b")
FileNotFoundError: [Errno 2] No such file or directory: '.compressed_tmp\\photo_2025-08-14_16-14-57 (15) — копия.jpg'
2025-08-14 23:03:16,006 | ERROR | Ошибка при сжатии D:\апап\photo_2025-08-14_16-14-57 (16) — копия — копия.jpg: [Errno 2] No such file or directory: '.compressed_tmp\\photo_2025-08-14_16-14-57 (16) — копия — копия.jpg'
Traceback (most recent call last):
  File "C:\Programms\JABot\upload_bot.py", line 55, in compress_image
    img.save(dst, format="JPEG", optimize=True, quality=75, progressive=True)
    ~~~~~~~~^^^^^^^^^^^^^^^^^^^^^^^^^^^^^^^^^^^^^^^^^^^^^^^^^^^^^^^^^^^^^^^^^
  File "C:\Programms\JABot\.venv\Lib\site-packages\PIL\Image.py", line 2583, in save
    fp = builtins.open(filename, "w+b")
FileNotFoundError: [Errno 2] No such file or directory: '.compressed_tmp\\photo_2025-08-14_16-14-57 (16) — копия — копия.jpg'
2025-08-14 23:03:16,015 | ERROR | Ошибка при сжатии D:\апап\photo_2025-08-14_16-14-57 (16) — копия.jpg: [Errno 2] No such file or directory: '.compressed_tmp\\photo_2025-08-14_16-14-57 (16) — копия.jpg'
Traceback (most recent call last):
  File "C:\Programms\JABot\upload_bot.py", line 55, in compress_image
    img.save(dst, format="JPEG", optimize=True, quality=75, progressive=True)
    ~~~~~~~~^^^^^^^^^^^^^^^^^^^^^^^^^^^^^^^^^^^^^^^^^^^^^^^^^^^^^^^^^^^^^^^^^
  File "C:\Programms\JABot\.venv\Lib\site-packages\PIL\Image.py", line 2583, in save
    fp = builtins.open(filename, "w+b")
FileNotFoundError: [Errno 2] No such file or directory: '.compressed_tmp\\photo_2025-08-14_16-14-57 (16) — копия.jpg'
2025-08-14 23:03:16,032 | ERROR | Ошибка при сжатии D:\апап\photo_2025-08-14_16-14-57 (17) — копия — копия.jpg: [Errno 2] No such file or directory: '.compressed_tmp\\photo_2025-08-14_16-14-57 (17) — копия — копия.jpg'
Traceback (most recent call last):
  File "C:\Programms\JABot\upload_bot.py", line 55, in compress_image
    img.save(dst, format="JPEG", optimize=True, quality=75, progressive=True)
    ~~~~~~~~^^^^^^^^^^^^^^^^^^^^^^^^^^^^^^^^^^^^^^^^^^^^^^^^^^^^^^^^^^^^^^^^^
  File "C:\Programms\JABot\.venv\Lib\site-packages\PIL\Image.py", line 2583, in save
    fp = builtins.open(filename, "w+b")
FileNotFoundError: [Errno 2] No such file or directory: '.compressed_tmp\\photo_2025-08-14_16-14-57 (17) — копия — копия.jpg'
2025-08-14 23:03:16,050 | ERROR | Ошибка при сжатии D:\апап\photo_2025-08-14_16-14-57 (17) — копия.jpg: [Errno 2] No such file or directory: '.compressed_tmp\\photo_2025-08-14_16-14-57 (17) — копия.jpg'
Traceback (most recent call last):
  File "C:\Programms\JABot\upload_bot.py", line 55, in compress_image
    img.save(dst, format="JPEG", optimize=True, quality=75, progressive=True)
    ~~~~~~~~^^^^^^^^^^^^^^^^^^^^^^^^^^^^^^^^^^^^^^^^^^^^^^^^^^^^^^^^^^^^^^^^^
  File "C:\Programms\JABot\.venv\Lib\site-packages\PIL\Image.py", line 2583, in save
    fp = builtins.open(filename, "w+b")
FileNotFoundError: [Errno 2] No such file or directory: '.compressed_tmp\\photo_2025-08-14_16-14-57 (17) — копия.jpg'
2025-08-14 23:03:16,058 | ERROR | Ошибка при сжатии D:\апап\photo_2025-08-14_16-14-57 (18) — копия — копия.jpg: [Errno 2] No such file or directory: '.compressed_tmp\\photo_2025-08-14_16-14-57 (18) — копия — копия.jpg'
Traceback (most recent call last):
  File "C:\Programms\JABot\upload_bot.py", line 55, in compress_image
    img.save(dst, format="JPEG", optimize=True, quality=75, progressive=True)
    ~~~~~~~~^^^^^^^^^^^^^^^^^^^^^^^^^^^^^^^^^^^^^^^^^^^^^^^^^^^^^^^^^^^^^^^^^
  File "C:\Programms\JABot\.venv\Lib\site-packages\PIL\Image.py", line 2583, in save
    fp = builtins.open(filename, "w+b")
FileNotFoundError: [Errno 2] No such file or directory: '.compressed_tmp\\photo_2025-08-14_16-14-57 (18) — копия — копия.jpg'
2025-08-14 23:03:16,066 | ERROR | Ошибка при сжатии D:\апап\photo_2025-08-14_16-14-57 (18) — копия.jpg: [Errno 2] No such file or directory: '.compressed_tmp\\photo_2025-08-14_16-14-57 (18) — копия.jpg'
Traceback (most recent call last):
  File "C:\Programms\JABot\upload_bot.py", line 55, in compress_image
    img.save(dst, format="JPEG", optimize=True, quality=75, progressive=True)
    ~~~~~~~~^^^^^^^^^^^^^^^^^^^^^^^^^^^^^^^^^^^^^^^^^^^^^^^^^^^^^^^^^^^^^^^^^
  File "C:\Programms\JABot\.venv\Lib\site-packages\PIL\Image.py", line 2583, in save
    fp = builtins.open(filename, "w+b")
FileNotFoundError: [Errno 2] No such file or directory: '.compressed_tmp\\photo_2025-08-14_16-14-57 (18) — копия.jpg'
2025-08-14 23:03:16,084 | ERROR | Ошибка при сжатии D:\апап\photo_2025-08-14_16-14-57 (19) — копия — копия.jpg: [Errno 2] No such file or directory: '.compressed_tmp\\photo_2025-08-14_16-14-57 (19) — копия — копия.jpg'
Traceback (most recent call last):
  File "C:\Programms\JABot\upload_bot.py", line 55, in compress_image
    img.save(dst, format="JPEG", optimize=True, quality=75, progressive=True)
    ~~~~~~~~^^^^^^^^^^^^^^^^^^^^^^^^^^^^^^^^^^^^^^^^^^^^^^^^^^^^^^^^^^^^^^^^^
  File "C:\Programms\JABot\.venv\Lib\site-packages\PIL\Image.py", line 2583, in save
    fp = builtins.open(filename, "w+b")
FileNotFoundError: [Errno 2] No such file or directory: '.compressed_tmp\\photo_2025-08-14_16-14-57 (19) — копия — копия.jpg'
2025-08-14 23:03:16,102 | ERROR | Ошибка при сжатии D:\апап\photo_2025-08-14_16-14-57 (19) — копия.jpg: [Errno 2] No such file or directory: '.compressed_tmp\\photo_2025-08-14_16-14-57 (19) — копия.jpg'
Traceback (most recent call last):
  File "C:\Programms\JABot\upload_bot.py", line 55, in compress_image
    img.save(dst, format="JPEG", optimize=True, quality=75, progressive=True)
    ~~~~~~~~^^^^^^^^^^^^^^^^^^^^^^^^^^^^^^^^^^^^^^^^^^^^^^^^^^^^^^^^^^^^^^^^^
  File "C:\Programms\JABot\.venv\Lib\site-packages\PIL\Image.py", line 2583, in save
    fp = builtins.open(filename, "w+b")
FileNotFoundError: [Errno 2] No such file or directory: '.compressed_tmp\\photo_2025-08-14_16-14-57 (19) — копия.jpg'
2025-08-14 23:03:16,129 | ERROR | Ошибка при сжатии D:\апап\photo_2025-08-14_16-14-57 — копия.jpg: [Errno 2] No such file or directory: '.compressed_tmp\\photo_2025-08-14_16-14-57 — копия.jpg'
Traceback (most recent call last):
  File "C:\Programms\JABot\upload_bot.py", line 55, in compress_image
    img.save(dst, format="JPEG", optimize=True, quality=75, progressive=True)
    ~~~~~~~~^^^^^^^^^^^^^^^^^^^^^^^^^^^^^^^^^^^^^^^^^^^^^^^^^^^^^^^^^^^^^^^^^
  File "C:\Programms\JABot\.venv\Lib\site-packages\PIL\Image.py", line 2583, in save
    fp = builtins.open(filename, "w+b")
FileNotFoundError: [Errno 2] No such file or directory: '.compressed_tmp\\photo_2025-08-14_16-14-57 — копия.jpg'
2025-08-14 23:03:16,157 | ERROR | Ошибка при сжатии D:\апап\photo_2025-08-14_16-14-57.jpg: [Errno 2] No such file or directory: '.compressed_tmp\\photo_2025-08-14_16-14-57.jpg'
Traceback (most recent call last):
  File "C:\Programms\JABot\upload_bot.py", line 55, in compress_image
    img.save(dst, format="JPEG", optimize=True, quality=75, progressive=True)
    ~~~~~~~~^^^^^^^^^^^^^^^^^^^^^^^^^^^^^^^^^^^^^^^^^^^^^^^^^^^^^^^^^^^^^^^^^
  File "C:\Programms\JABot\.venv\Lib\site-packages\PIL\Image.py", line 2583, in save
    fp = builtins.open(filename, "w+b")
FileNotFoundError: [Errno 2] No such file or directory: '.compressed_tmp\\photo_2025-08-14_16-14-57.jpg'
2025-08-14 23:03:16,176 | ERROR | Ошибка при сжатии D:\апап\с — копия.jpg: [Errno 2] No such file or directory: '.compressed_tmp\\с — копия.jpg'
Traceback (most recent call last):
  File "C:\Programms\JABot\upload_bot.py", line 55, in compress_image
    img.save(dst, format="JPEG", optimize=True, quality=75, progressive=True)
    ~~~~~~~~^^^^^^^^^^^^^^^^^^^^^^^^^^^^^^^^^^^^^^^^^^^^^^^^^^^^^^^^^^^^^^^^^
  File "C:\Programms\JABot\.venv\Lib\site-packages\PIL\Image.py", line 2583, in save
    fp = builtins.open(filename, "w+b")
FileNotFoundError: [Errno 2] No such file or directory: '.compressed_tmp\\с — копия.jpg'
2025-08-14 23:03:16,196 | ERROR | Ошибка при сжатии D:\апап\с.jpg: [Errno 2] No such file or directory: '.compressed_tmp\\с.jpg'
Traceback (most recent call last):
  File "C:\Programms\JABot\upload_bot.py", line 55, in compress_image
    img.save(dst, format="JPEG", optimize=True, quality=75, progressive=True)
    ~~~~~~~~^^^^^^^^^^^^^^^^^^^^^^^^^^^^^^^^^^^^^^^^^^^^^^^^^^^^^^^^^^^^^^^^^
  File "C:\Programms\JABot\.venv\Lib\site-packages\PIL\Image.py", line 2583, in save
    fp = builtins.open(filename, "w+b")
FileNotFoundError: [Errno 2] No such file or directory: '.compressed_tmp\\с.jpg'
2025-08-14 23:03:46,051 | INFO | HTTP Request: POST https://api.telegram.org/bot8307958255:AAHOXk2JP0_j-lBh8Xf48lRX180J7GKRMpQ/sendMediaGroup "HTTP/1.1 200 OK"
2025-08-14 23:04:48,807 | INFO | HTTP Request: POST https://api.telegram.org/bot8307958255:AAHOXk2JP0_j-lBh8Xf48lRX180J7GKRMpQ/sendMediaGroup "HTTP/1.1 200 OK"
2025-08-14 23:41:06,660 | WARNING | Сетевая ошибка (Timed out). Попытка #1. Ждём 2 сек...
2025-08-14 23:41:14,824 | INFO | HTTP Request: POST https://api.telegram.org/bot8307958255:AAHOXk2JP0_j-lBh8Xf48lRX180J7GKRMpQ/sendMediaGroup "HTTP/1.1 200 OK"
2025-08-14 23:41:24,437 | INFO | HTTP Request: POST https://api.telegram.org/bot8307958255:AAHOXk2JP0_j-lBh8Xf48lRX180J7GKRMpQ/sendMediaGroup "HTTP/1.1 200 OK"
2025-08-14 23:41:28,496 | ERROR | Не удалось подготовить файл .compressed_tmp\photo_2025-08-14_16-14-57 (14) — копия — копия.jpg: [Errno 2] No such file or directory: '.compressed_tmp\\photo_2025-08-14_16-14-57 (14) — копия — копия.jpg'
Traceback (most recent call last):
  File "C:\Programms\JABot\upload_bot.py", line 174, in process_upload
    f = open(str(p), "rb")
FileNotFoundError: [Errno 2] No such file or directory: '.compressed_tmp\\photo_2025-08-14_16-14-57 (14) — копия — копия.jpg'
2025-08-14 23:41:28,497 | ERROR | Не удалось подготовить файл .compressed_tmp\photo_2025-08-14_16-14-57 (14) — копия.jpg: [Errno 2] No such file or directory: '.compressed_tmp\\photo_2025-08-14_16-14-57 (14) — копия.jpg'
Traceback (most recent call last):
  File "C:\Programms\JABot\upload_bot.py", line 174, in process_upload
    f = open(str(p), "rb")
FileNotFoundError: [Errno 2] No such file or directory: '.compressed_tmp\\photo_2025-08-14_16-14-57 (14) — копия.jpg'
2025-08-14 23:41:28,497 | ERROR | Не удалось подготовить файл .compressed_tmp\photo_2025-08-14_16-14-57 (15) — копия — копия.jpg: [Errno 2] No such file or directory: '.compressed_tmp\\photo_2025-08-14_16-14-57 (15) — копия — копия.jpg'
Traceback (most recent call last):
  File "C:\Programms\JABot\upload_bot.py", line 174, in process_upload
    f = open(str(p), "rb")
FileNotFoundError: [Errno 2] No such file or directory: '.compressed_tmp\\photo_2025-08-14_16-14-57 (15) — копия — копия.jpg'
2025-08-14 23:41:28,498 | ERROR | Не удалось подготовить файл .compressed_tmp\photo_2025-08-14_16-14-57 (15) — копия.jpg: [Errno 2] No such file or directory: '.compressed_tmp\\photo_2025-08-14_16-14-57 (15) — копия.jpg'
Traceback (most recent call last):
  File "C:\Programms\JABot\upload_bot.py", line 174, in process_upload
    f = open(str(p), "rb")
FileNotFoundError: [Errno 2] No such file or directory: '.compressed_tmp\\photo_2025-08-14_16-14-57 (15) — копия.jpg'
2025-08-14 23:41:28,498 | ERROR | Не удалось подготовить файл .compressed_tmp\photo_2025-08-14_16-14-57 (16) — копия — копия.jpg: [Errno 2] No such file or directory: '.compressed_tmp\\photo_2025-08-14_16-14-57 (16) — копия — копия.jpg'
Traceback (most recent call last):
  File "C:\Programms\JABot\upload_bot.py", line 174, in process_upload
    f = open(str(p), "rb")
FileNotFoundError: [Errno 2] No such file or directory: '.compressed_tmp\\photo_2025-08-14_16-14-57 (16) — копия — копия.jpg'
2025-08-14 23:41:28,498 | ERROR | Не удалось подготовить файл .compressed_tmp\photo_2025-08-14_16-14-57 (16) — копия.jpg: [Errno 2] No such file or directory: '.compressed_tmp\\photo_2025-08-14_16-14-57 (16) — копия.jpg'
Traceback (most recent call last):
  File "C:\Programms\JABot\upload_bot.py", line 174, in process_upload
    f = open(str(p), "rb")
FileNotFoundError: [Errno 2] No such file or directory: '.compressed_tmp\\photo_2025-08-14_16-14-57 (16) — копия.jpg'
2025-08-14 23:41:28,499 | ERROR | Не удалось подготовить файл .compressed_tmp\photo_2025-08-14_16-14-57 (17) — копия — копия.jpg: [Errno 2] No such file or directory: '.compressed_tmp\\photo_2025-08-14_16-14-57 (17) — копия — копия.jpg'
Traceback (most recent call last):
  File "C:\Programms\JABot\upload_bot.py", line 174, in process_upload
    f = open(str(p), "rb")
FileNotFoundError: [Errno 2] No such file or directory: '.compressed_tmp\\photo_2025-08-14_16-14-57 (17) — копия — копия.jpg'
2025-08-14 23:41:28,499 | ERROR | Не удалось подготовить файл .compressed_tmp\photo_2025-08-14_16-14-57 (17) — копия.jpg: [Errno 2] No such file or directory: '.compressed_tmp\\photo_2025-08-14_16-14-57 (17) — копия.jpg'
Traceback (most recent call last):
  File "C:\Programms\JABot\upload_bot.py", line 174, in process_upload
    f = open(str(p), "rb")
FileNotFoundError: [Errno 2] No such file or directory: '.compressed_tmp\\photo_2025-08-14_16-14-57 (17) — копия.jpg'
2025-08-14 23:41:28,501 | ERROR | Не удалось подготовить файл .compressed_tmp\photo_2025-08-14_16-14-57 (18) — копия — копия.jpg: [Errno 2] No such file or directory: '.compressed_tmp\\photo_2025-08-14_16-14-57 (18) — копия — копия.jpg'
Traceback (most recent call last):
  File "C:\Programms\JABot\upload_bot.py", line 174, in process_upload
    f = open(str(p), "rb")
FileNotFoundError: [Errno 2] No such file or directory: '.compressed_tmp\\photo_2025-08-14_16-14-57 (18) — копия — копия.jpg'
2025-08-14 23:41:28,502 | ERROR | Не удалось подготовить файл .compressed_tmp\photo_2025-08-14_16-14-57 (18) — копия.jpg: [Errno 2] No such file or directory: '.compressed_tmp\\photo_2025-08-14_16-14-57 (18) — копия.jpg'
Traceback (most recent call last):
  File "C:\Programms\JABot\upload_bot.py", line 174, in process_upload
    f = open(str(p), "rb")
FileNotFoundError: [Errno 2] No such file or directory: '.compressed_tmp\\photo_2025-08-14_16-14-57 (18) — копия.jpg'
2025-08-14 23:41:28,502 | ERROR | Не удалось подготовить файл .compressed_tmp\photo_2025-08-14_16-14-57 (19) — копия — копия.jpg: [Errno 2] No such file or directory: '.compressed_tmp\\photo_2025-08-14_16-14-57 (19) — копия — копия.jpg'
Traceback (most recent call last):
  File "C:\Programms\JABot\upload_bot.py", line 174, in process_upload
    f = open(str(p), "rb")
FileNotFoundError: [Errno 2] No such file or directory: '.compressed_tmp\\photo_2025-08-14_16-14-57 (19) — копия — копия.jpg'
2025-08-14 23:41:28,502 | ERROR | Не удалось подготовить файл .compressed_tmp\photo_2025-08-14_16-14-57 (19) — копия.jpg: [Errno 2] No such file or directory: '.compressed_tmp\\photo_2025-08-14_16-14-57 (19) — копия.jpg'
Traceback (most recent call last):
  File "C:\Programms\JABot\upload_bot.py", line 174, in process_upload
    f = open(str(p), "rb")
FileNotFoundError: [Errno 2] No such file or directory: '.compressed_tmp\\photo_2025-08-14_16-14-57 (19) — копия.jpg'
2025-08-14 23:41:28,503 | ERROR | Не удалось подготовить файл .compressed_tmp\photo_2025-08-14_16-14-57 — копия.jpg: [Errno 2] No such file or directory: '.compressed_tmp\\photo_2025-08-14_16-14-57 — копия.jpg'
Traceback (most recent call last):
  File "C:\Programms\JABot\upload_bot.py", line 174, in process_upload
    f = open(str(p), "rb")
FileNotFoundError: [Errno 2] No such file or directory: '.compressed_tmp\\photo_2025-08-14_16-14-57 — копия.jpg'
2025-08-14 23:41:28,503 | ERROR | Не удалось подготовить файл .compressed_tmp\photo_2025-08-14_16-14-57.jpg: [Errno 2] No such file or directory: '.compressed_tmp\\photo_2025-08-14_16-14-57.jpg'
Traceback (most recent call last):
  File "C:\Programms\JABot\upload_bot.py", line 174, in process_upload
    f = open(str(p), "rb")
FileNotFoundError: [Errno 2] No such file or directory: '.compressed_tmp\\photo_2025-08-14_16-14-57.jpg'
2025-08-14 23:41:28,503 | ERROR | Не удалось подготовить файл .compressed_tmp\с — копия.jpg: [Errno 2] No such file or directory: '.compressed_tmp\\с — копия.jpg'
Traceback (most recent call last):
  File "C:\Programms\JABot\upload_bot.py", line 174, in process_upload
    f = open(str(p), "rb")
FileNotFoundError: [Errno 2] No such file or directory: '.compressed_tmp\\с — копия.jpg'
2025-08-14 23:41:28,503 | ERROR | Не удалось подготовить файл .compressed_tmp\с.jpg: [Errno 2] No such file or directory: '.compressed_tmp\\с.jpg'
Traceback (most recent call last):
  File "C:\Programms\JABot\upload_bot.py", line 174, in process_upload
    f = open(str(p), "rb")
FileNotFoundError: [Errno 2] No such file or directory: '.compressed_tmp\\с.jpg'
2025-08-14 23:42:15,585 | WARNING | Сетевая ошибка (Timed out). Попытка #1. Ждём 2 сек...
2025-08-14 23:42:22,611 | WARNING | Сетевая ошибка (Timed out). Попытка #2. Ждём 4 сек...
2025-08-14 23:42:29,207 | INFO | HTTP Request: POST https://api.telegram.org/bot8307958255:AAHOXk2JP0_j-lBh8Xf48lRX180J7GKRMpQ/sendMediaGroup "HTTP/1.1 200 OK"
2025-08-14 23:42:36,226 | INFO | HTTP Request: POST https://api.telegram.org/bot8307958255:AAHOXk2JP0_j-lBh8Xf48lRX180J7GKRMpQ/sendMediaGroup "HTTP/1.1 200 OK"
2025-08-14 23:42:56,177 | ERROR | Не удалось подготовить файл .compressed_tmp\photo_2025-08-14_16-14-57 (14) — копия — копия.jpg: [Errno 2] No such file or directory: '.compressed_tmp\\photo_2025-08-14_16-14-57 (14) — копия — копия.jpg'
Traceback (most recent call last):
  File "C:\Programms\JABot\upload_bot.py", line 174, in process_upload
    f = open(str(p), "rb")
FileNotFoundError: [Errno 2] No such file or directory: '.compressed_tmp\\photo_2025-08-14_16-14-57 (14) — копия — копия.jpg'
2025-08-14 23:42:56,178 | ERROR | Не удалось подготовить файл .compressed_tmp\photo_2025-08-14_16-14-57 (14) — копия.jpg: [Errno 2] No such file or directory: '.compressed_tmp\\photo_2025-08-14_16-14-57 (14) — копия.jpg'
Traceback (most recent call last):
  File "C:\Programms\JABot\upload_bot.py", line 174, in process_upload
    f = open(str(p), "rb")
FileNotFoundError: [Errno 2] No such file or directory: '.compressed_tmp\\photo_2025-08-14_16-14-57 (14) — копия.jpg'
2025-08-14 23:42:56,178 | ERROR | Не удалось подготовить файл .compressed_tmp\photo_2025-08-14_16-14-57 (15) — копия — копия.jpg: [Errno 2] No such file or directory: '.compressed_tmp\\photo_2025-08-14_16-14-57 (15) — копия — копия.jpg'
Traceback (most recent call last):
  File "C:\Programms\JABot\upload_bot.py", line 174, in process_upload
    f = open(str(p), "rb")
FileNotFoundError: [Errno 2] No such file or directory: '.compressed_tmp\\photo_2025-08-14_16-14-57 (15) — копия — копия.jpg'
2025-08-14 23:42:56,179 | ERROR | Не удалось подготовить файл .compressed_tmp\photo_2025-08-14_16-14-57 (15) — копия.jpg: [Errno 2] No such file or directory: '.compressed_tmp\\photo_2025-08-14_16-14-57 (15) — копия.jpg'
Traceback (most recent call last):
  File "C:\Programms\JABot\upload_bot.py", line 174, in process_upload
    f = open(str(p), "rb")
FileNotFoundError: [Errno 2] No such file or directory: '.compressed_tmp\\photo_2025-08-14_16-14-57 (15) — копия.jpg'
2025-08-14 23:42:56,179 | ERROR | Не удалось подготовить файл .compressed_tmp\photo_2025-08-14_16-14-57 (16) — копия — копия.jpg: [Errno 2] No such file or directory: '.compressed_tmp\\photo_2025-08-14_16-14-57 (16) — копия — копия.jpg'
Traceback (most recent call last):
  File "C:\Programms\JABot\upload_bot.py", line 174, in process_upload
    f = open(str(p), "rb")
FileNotFoundError: [Errno 2] No such file or directory: '.compressed_tmp\\photo_2025-08-14_16-14-57 (16) — копия — копия.jpg'
2025-08-14 23:42:56,179 | ERROR | Не удалось подготовить файл .compressed_tmp\photo_2025-08-14_16-14-57 (16) — копия.jpg: [Errno 2] No such file or directory: '.compressed_tmp\\photo_2025-08-14_16-14-57 (16) — копия.jpg'
Traceback (most recent call last):
  File "C:\Programms\JABot\upload_bot.py", line 174, in process_upload
    f = open(str(p), "rb")
FileNotFoundError: [Errno 2] No such file or directory: '.compressed_tmp\\photo_2025-08-14_16-14-57 (16) — копия.jpg'
2025-08-14 23:42:56,180 | ERROR | Не удалось подготовить файл .compressed_tmp\photo_2025-08-14_16-14-57 (17) — копия — копия.jpg: [Errno 2] No such file or directory: '.compressed_tmp\\photo_2025-08-14_16-14-57 (17) — копия — копия.jpg'
Traceback (most recent call last):
  File "C:\Programms\JABot\upload_bot.py", line 174, in process_upload
    f = open(str(p), "rb")
FileNotFoundError: [Errno 2] No such file or directory: '.compressed_tmp\\photo_2025-08-14_16-14-57 (17) — копия — копия.jpg'
2025-08-14 23:42:56,180 | ERROR | Не удалось подготовить файл .compressed_tmp\photo_2025-08-14_16-14-57 (17) — копия.jpg: [Errno 2] No such file or directory: '.compressed_tmp\\photo_2025-08-14_16-14-57 (17) — копия.jpg'
Traceback (most recent call last):
  File "C:\Programms\JABot\upload_bot.py", line 174, in process_upload
    f = open(str(p), "rb")
FileNotFoundError: [Errno 2] No such file or directory: '.compressed_tmp\\photo_2025-08-14_16-14-57 (17) — копия.jpg'
2025-08-14 23:42:56,182 | ERROR | Не удалось подготовить файл .compressed_tmp\photo_2025-08-14_16-14-57 (18) — копия — копия.jpg: [Errno 2] No such file or directory: '.compressed_tmp\\photo_2025-08-14_16-14-57 (18) — копия — копия.jpg'
Traceback (most recent call last):
  File "C:\Programms\JABot\upload_bot.py", line 174, in process_upload
    f = open(str(p), "rb")
FileNotFoundError: [Errno 2] No such file or directory: '.compressed_tmp\\photo_2025-08-14_16-14-57 (18) — копия — копия.jpg'
2025-08-14 23:42:56,183 | ERROR | Не удалось подготовить файл .compressed_tmp\photo_2025-08-14_16-14-57 (18) — копия.jpg: [Errno 2] No such file or directory: '.compressed_tmp\\photo_2025-08-14_16-14-57 (18) — копия.jpg'
Traceback (most recent call last):
  File "C:\Programms\JABot\upload_bot.py", line 174, in process_upload
    f = open(str(p), "rb")
FileNotFoundError: [Errno 2] No such file or directory: '.compressed_tmp\\photo_2025-08-14_16-14-57 (18) — копия.jpg'
2025-08-14 23:42:56,183 | ERROR | Не удалось подготовить файл .compressed_tmp\photo_2025-08-14_16-14-57 (19) — копия — копия.jpg: [Errno 2] No such file or directory: '.compressed_tmp\\photo_2025-08-14_16-14-57 (19) — копия — копия.jpg'
Traceback (most recent call last):
  File "C:\Programms\JABot\upload_bot.py", line 174, in process_upload
    f = open(str(p), "rb")
FileNotFoundError: [Errno 2] No such file or directory: '.compressed_tmp\\photo_2025-08-14_16-14-57 (19) — копия — копия.jpg'
2025-08-14 23:42:56,183 | ERROR | Не удалось подготовить файл .compressed_tmp\photo_2025-08-14_16-14-57 (19) — копия.jpg: [Errno 2] No such file or directory: '.compressed_tmp\\photo_2025-08-14_16-14-57 (19) — копия.jpg'
Traceback (most recent call last):
  File "C:\Programms\JABot\upload_bot.py", line 174, in process_upload
    f = open(str(p), "rb")
FileNotFoundError: [Errno 2] No such file or directory: '.compressed_tmp\\photo_2025-08-14_16-14-57 (19) — копия.jpg'
2025-08-14 23:42:56,184 | ERROR | Не удалось подготовить файл .compressed_tmp\photo_2025-08-14_16-14-57 — копия.jpg: [Errno 2] No such file or directory: '.compressed_tmp\\photo_2025-08-14_16-14-57 — копия.jpg'
Traceback (most recent call last):
  File "C:\Programms\JABot\upload_bot.py", line 174, in process_upload
    f = open(str(p), "rb")
FileNotFoundError: [Errno 2] No such file or directory: '.compressed_tmp\\photo_2025-08-14_16-14-57 — копия.jpg'
2025-08-14 23:42:56,184 | ERROR | Не удалось подготовить файл .compressed_tmp\photo_2025-08-14_16-14-57.jpg: [Errno 2] No such file or directory: '.compressed_tmp\\photo_2025-08-14_16-14-57.jpg'
Traceback (most recent call last):
  File "C:\Programms\JABot\upload_bot.py", line 174, in process_upload
    f = open(str(p), "rb")
FileNotFoundError: [Errno 2] No such file or directory: '.compressed_tmp\\photo_2025-08-14_16-14-57.jpg'
2025-08-14 23:42:56,184 | ERROR | Не удалось подготовить файл .compressed_tmp\с — копия.jpg: [Errno 2] No such file or directory: '.compressed_tmp\\с — копия.jpg'
Traceback (most recent call last):
  File "C:\Programms\JABot\upload_bot.py", line 174, in process_upload
    f = open(str(p), "rb")
FileNotFoundError: [Errno 2] No such file or directory: '.compressed_tmp\\с — копия.jpg'
2025-08-14 23:42:56,184 | ERROR | Не удалось подготовить файл .compressed_tmp\с.jpg: [Errno 2] No such file or directory: '.compressed_tmp\\с.jpg'
Traceback (most recent call last):
  File "C:\Programms\JABot\upload_bot.py", line 174, in process_upload
    f = open(str(p), "rb")
FileNotFoundError: [Errno 2] No such file or directory: '.compressed_tmp\\с.jpg'
2025-08-14 23:45:50,148 | INFO | HTTP Request: POST https://api.telegram.org/bot8307958255:AAHOXk2JP0_j-lBh8Xf48lRX180J7GKRMpQ/sendMediaGroup "HTTP/1.1 200 OK"
2025-08-14 23:45:58,089 | INFO | HTTP Request: POST https://api.telegram.org/bot8307958255:AAHOXk2JP0_j-lBh8Xf48lRX180J7GKRMpQ/sendMediaGroup "HTTP/1.1 200 OK"
2025-08-14 23:46:06,809 | ERROR | Не удалось подготовить файл .compressed_tmp\photo_2025-08-14_16-14-57 (14) — копия — копия.jpg: [Errno 2] No such file or directory: '.compressed_tmp\\photo_2025-08-14_16-14-57 (14) — копия — копия.jpg'
Traceback (most recent call last):
  File "C:\Programms\JABot\upload_bot.py", line 174, in process_upload
    f = open(str(p), "rb")
FileNotFoundError: [Errno 2] No such file or directory: '.compressed_tmp\\photo_2025-08-14_16-14-57 (14) — копия — копия.jpg'
2025-08-14 23:46:06,810 | ERROR | Не удалось подготовить файл .compressed_tmp\photo_2025-08-14_16-14-57 (14) — копия.jpg: [Errno 2] No such file or directory: '.compressed_tmp\\photo_2025-08-14_16-14-57 (14) — копия.jpg'
Traceback (most recent call last):
  File "C:\Programms\JABot\upload_bot.py", line 174, in process_upload
    f = open(str(p), "rb")
FileNotFoundError: [Errno 2] No such file or directory: '.compressed_tmp\\photo_2025-08-14_16-14-57 (14) — копия.jpg'
2025-08-14 23:46:06,810 | ERROR | Не удалось подготовить файл .compressed_tmp\photo_2025-08-14_16-14-57 (15) — копия — копия.jpg: [Errno 2] No such file or directory: '.compressed_tmp\\photo_2025-08-14_16-14-57 (15) — копия — копия.jpg'
Traceback (most recent call last):
  File "C:\Programms\JABot\upload_bot.py", line 174, in process_upload
    f = open(str(p), "rb")
FileNotFoundError: [Errno 2] No such file or directory: '.compressed_tmp\\photo_2025-08-14_16-14-57 (15) — копия — копия.jpg'
2025-08-14 23:46:06,811 | ERROR | Не удалось подготовить файл .compressed_tmp\photo_2025-08-14_16-14-57 (15) — копия.jpg: [Errno 2] No such file or directory: '.compressed_tmp\\photo_2025-08-14_16-14-57 (15) — копия.jpg'
Traceback (most recent call last):
  File "C:\Programms\JABot\upload_bot.py", line 174, in process_upload
    f = open(str(p), "rb")
FileNotFoundError: [Errno 2] No such file or directory: '.compressed_tmp\\photo_2025-08-14_16-14-57 (15) — копия.jpg'
2025-08-14 23:46:06,811 | ERROR | Не удалось подготовить файл .compressed_tmp\photo_2025-08-14_16-14-57 (16) — копия — копия.jpg: [Errno 2] No such file or directory: '.compressed_tmp\\photo_2025-08-14_16-14-57 (16) — копия — копия.jpg'
Traceback (most recent call last):
  File "C:\Programms\JABot\upload_bot.py", line 174, in process_upload
    f = open(str(p), "rb")
FileNotFoundError: [Errno 2] No such file or directory: '.compressed_tmp\\photo_2025-08-14_16-14-57 (16) — копия — копия.jpg'
2025-08-14 23:46:06,811 | ERROR | Не удалось подготовить файл .compressed_tmp\photo_2025-08-14_16-14-57 (16) — копия.jpg: [Errno 2] No such file or directory: '.compressed_tmp\\photo_2025-08-14_16-14-57 (16) — копия.jpg'
Traceback (most recent call last):
  File "C:\Programms\JABot\upload_bot.py", line 174, in process_upload
    f = open(str(p), "rb")
FileNotFoundError: [Errno 2] No such file or directory: '.compressed_tmp\\photo_2025-08-14_16-14-57 (16) — копия.jpg'
2025-08-14 23:46:06,812 | ERROR | Не удалось подготовить файл .compressed_tmp\photo_2025-08-14_16-14-57 (17) — копия — копия.jpg: [Errno 2] No such file or directory: '.compressed_tmp\\photo_2025-08-14_16-14-57 (17) — копия — копия.jpg'
Traceback (most recent call last):
  File "C:\Programms\JABot\upload_bot.py", line 174, in process_upload
    f = open(str(p), "rb")
FileNotFoundError: [Errno 2] No such file or directory: '.compressed_tmp\\photo_2025-08-14_16-14-57 (17) — копия — копия.jpg'
2025-08-14 23:46:06,812 | ERROR | Не удалось подготовить файл .compressed_tmp\photo_2025-08-14_16-14-57 (17) — копия.jpg: [Errno 2] No such file or directory: '.compressed_tmp\\photo_2025-08-14_16-14-57 (17) — копия.jpg'
Traceback (most recent call last):
  File "C:\Programms\JABot\upload_bot.py", line 174, in process_upload
    f = open(str(p), "rb")
FileNotFoundError: [Errno 2] No such file or directory: '.compressed_tmp\\photo_2025-08-14_16-14-57 (17) — копия.jpg'
2025-08-14 23:46:06,812 | ERROR | Не удалось подготовить файл .compressed_tmp\photo_2025-08-14_16-14-57 (18) — копия — копия.jpg: [Errno 2] No such file or directory: '.compressed_tmp\\photo_2025-08-14_16-14-57 (18) — копия — копия.jpg'
Traceback (most recent call last):
  File "C:\Programms\JABot\upload_bot.py", line 174, in process_upload
    f = open(str(p), "rb")
FileNotFoundError: [Errno 2] No such file or directory: '.compressed_tmp\\photo_2025-08-14_16-14-57 (18) — копия — копия.jpg'
2025-08-14 23:46:06,812 | ERROR | Не удалось подготовить файл .compressed_tmp\photo_2025-08-14_16-14-57 (18) — копия.jpg: [Errno 2] No such file or directory: '.compressed_tmp\\photo_2025-08-14_16-14-57 (18) — копия.jpg'
Traceback (most recent call last):
  File "C:\Programms\JABot\upload_bot.py", line 174, in process_upload
    f = open(str(p), "rb")
FileNotFoundError: [Errno 2] No such file or directory: '.compressed_tmp\\photo_2025-08-14_16-14-57 (18) — копия.jpg'
2025-08-14 23:46:06,813 | ERROR | Не удалось подготовить файл .compressed_tmp\photo_2025-08-14_16-14-57 (19) — копия — копия.jpg: [Errno 2] No such file or directory: '.compressed_tmp\\photo_2025-08-14_16-14-57 (19) — копия — копия.jpg'
Traceback (most recent call last):
  File "C:\Programms\JABot\upload_bot.py", line 174, in process_upload
    f = open(str(p), "rb")
FileNotFoundError: [Errno 2] No such file or directory: '.compressed_tmp\\photo_2025-08-14_16-14-57 (19) — копия — копия.jpg'
2025-08-14 23:46:06,813 | ERROR | Не удалось подготовить файл .compressed_tmp\photo_2025-08-14_16-14-57 (19) — копия.jpg: [Errno 2] No such file or directory: '.compressed_tmp\\photo_2025-08-14_16-14-57 (19) — копия.jpg'
Traceback (most recent call last):
  File "C:\Programms\JABot\upload_bot.py", line 174, in process_upload
    f = open(str(p), "rb")
FileNotFoundError: [Errno 2] No such file or directory: '.compressed_tmp\\photo_2025-08-14_16-14-57 (19) — копия.jpg'
2025-08-14 23:46:06,813 | ERROR | Не удалось подготовить файл .compressed_tmp\photo_2025-08-14_16-14-57 — копия.jpg: [Errno 2] No such file or directory: '.compressed_tmp\\photo_2025-08-14_16-14-57 — копия.jpg'
Traceback (most recent call last):
  File "C:\Programms\JABot\upload_bot.py", line 174, in process_upload
    f = open(str(p), "rb")
FileNotFoundError: [Errno 2] No such file or directory: '.compressed_tmp\\photo_2025-08-14_16-14-57 — копия.jpg'
2025-08-14 23:46:06,814 | ERROR | Не удалось подготовить файл .compressed_tmp\photo_2025-08-14_16-14-57.jpg: [Errno 2] No such file or directory: '.compressed_tmp\\photo_2025-08-14_16-14-57.jpg'
Traceback (most recent call last):
  File "C:\Programms\JABot\upload_bot.py", line 174, in process_upload
    f = open(str(p), "rb")
FileNotFoundError: [Errno 2] No such file or directory: '.compressed_tmp\\photo_2025-08-14_16-14-57.jpg'
2025-08-14 23:46:06,814 | ERROR | Не удалось подготовить файл .compressed_tmp\с — копия.jpg: [Errno 2] No such file or directory: '.compressed_tmp\\с — копия.jpg'
Traceback (most recent call last):
  File "C:\Programms\JABot\upload_bot.py", line 174, in process_upload
    f = open(str(p), "rb")
FileNotFoundError: [Errno 2] No such file or directory: '.compressed_tmp\\с — копия.jpg'
2025-08-14 23:46:06,814 | ERROR | Не удалось подготовить файл .compressed_tmp\с.jpg: [Errno 2] No such file or directory: '.compressed_tmp\\с.jpg'
Traceback (most recent call last):
  File "C:\Programms\JABot\upload_bot.py", line 174, in process_upload
    f = open(str(p), "rb")
FileNotFoundError: [Errno 2] No such file or directory: '.compressed_tmp\\с.jpg'
2025-08-14 23:46:14,903 | ERROR | Ошибка при сжатии D:\апап\photo_2025-08-14_16-14-57 (14) — копия — копия.jpg: [Errno 2] No such file or directory: '.compressed_tmp\\photo_2025-08-14_16-14-57 (14) — копия — копия.jpg'
Traceback (most recent call last):
  File "C:\Programms\JABot\upload_bot.py", line 55, in compress_image
    img.save(dst, format="JPEG", optimize=True, quality=75, progressive=True)
    ~~~~~~~~^^^^^^^^^^^^^^^^^^^^^^^^^^^^^^^^^^^^^^^^^^^^^^^^^^^^^^^^^^^^^^^^^
  File "C:\Programms\JABot\.venv\Lib\site-packages\PIL\Image.py", line 2583, in save
    fp = builtins.open(filename, "w+b")
FileNotFoundError: [Errno 2] No such file or directory: '.compressed_tmp\\photo_2025-08-14_16-14-57 (14) — копия — копия.jpg'
2025-08-14 23:46:14,912 | ERROR | Ошибка при сжатии D:\апап\photo_2025-08-14_16-14-57 (14) — копия.jpg: [Errno 2] No such file or directory: '.compressed_tmp\\photo_2025-08-14_16-14-57 (14) — копия.jpg'
Traceback (most recent call last):
  File "C:\Programms\JABot\upload_bot.py", line 55, in compress_image
    img.save(dst, format="JPEG", optimize=True, quality=75, progressive=True)
    ~~~~~~~~^^^^^^^^^^^^^^^^^^^^^^^^^^^^^^^^^^^^^^^^^^^^^^^^^^^^^^^^^^^^^^^^^
  File "C:\Programms\JABot\.venv\Lib\site-packages\PIL\Image.py", line 2583, in save
    fp = builtins.open(filename, "w+b")
FileNotFoundError: [Errno 2] No such file or directory: '.compressed_tmp\\photo_2025-08-14_16-14-57 (14) — копия.jpg'
2025-08-14 23:46:14,930 | ERROR | Ошибка при сжатии D:\апап\photo_2025-08-14_16-14-57 (15) — копия — копия.jpg: [Errno 2] No such file or directory: '.compressed_tmp\\photo_2025-08-14_16-14-57 (15) — копия — копия.jpg'
Traceback (most recent call last):
  File "C:\Programms\JABot\upload_bot.py", line 55, in compress_image
    img.save(dst, format="JPEG", optimize=True, quality=75, progressive=True)
    ~~~~~~~~^^^^^^^^^^^^^^^^^^^^^^^^^^^^^^^^^^^^^^^^^^^^^^^^^^^^^^^^^^^^^^^^^
  File "C:\Programms\JABot\.venv\Lib\site-packages\PIL\Image.py", line 2583, in save
    fp = builtins.open(filename, "w+b")
FileNotFoundError: [Errno 2] No such file or directory: '.compressed_tmp\\photo_2025-08-14_16-14-57 (15) — копия — копия.jpg'
2025-08-14 23:46:14,948 | ERROR | Ошибка при сжатии D:\апап\photo_2025-08-14_16-14-57 (15) — копия.jpg: [Errno 2] No such file or directory: '.compressed_tmp\\photo_2025-08-14_16-14-57 (15) — копия.jpg'
Traceback (most recent call last):
  File "C:\Programms\JABot\upload_bot.py", line 55, in compress_image
    img.save(dst, format="JPEG", optimize=True, quality=75, progressive=True)
    ~~~~~~~~^^^^^^^^^^^^^^^^^^^^^^^^^^^^^^^^^^^^^^^^^^^^^^^^^^^^^^^^^^^^^^^^^
  File "C:\Programms\JABot\.venv\Lib\site-packages\PIL\Image.py", line 2583, in save
    fp = builtins.open(filename, "w+b")
FileNotFoundError: [Errno 2] No such file or directory: '.compressed_tmp\\photo_2025-08-14_16-14-57 (15) — копия.jpg'
2025-08-14 23:46:14,956 | ERROR | Ошибка при сжатии D:\апап\photo_2025-08-14_16-14-57 (16) — копия — копия.jpg: [Errno 2] No such file or directory: '.compressed_tmp\\photo_2025-08-14_16-14-57 (16) — копия — копия.jpg'
Traceback (most recent call last):
  File "C:\Programms\JABot\upload_bot.py", line 55, in compress_image
    img.save(dst, format="JPEG", optimize=True, quality=75, progressive=True)
    ~~~~~~~~^^^^^^^^^^^^^^^^^^^^^^^^^^^^^^^^^^^^^^^^^^^^^^^^^^^^^^^^^^^^^^^^^
  File "C:\Programms\JABot\.venv\Lib\site-packages\PIL\Image.py", line 2583, in save
    fp = builtins.open(filename, "w+b")
FileNotFoundError: [Errno 2] No such file or directory: '.compressed_tmp\\photo_2025-08-14_16-14-57 (16) — копия — копия.jpg'
2025-08-14 23:46:14,964 | ERROR | Ошибка при сжатии D:\апап\photo_2025-08-14_16-14-57 (16) — копия.jpg: [Errno 2] No such file or directory: '.compressed_tmp\\photo_2025-08-14_16-14-57 (16) — копия.jpg'
Traceback (most recent call last):
  File "C:\Programms\JABot\upload_bot.py", line 55, in compress_image
    img.save(dst, format="JPEG", optimize=True, quality=75, progressive=True)
    ~~~~~~~~^^^^^^^^^^^^^^^^^^^^^^^^^^^^^^^^^^^^^^^^^^^^^^^^^^^^^^^^^^^^^^^^^
  File "C:\Programms\JABot\.venv\Lib\site-packages\PIL\Image.py", line 2583, in save
    fp = builtins.open(filename, "w+b")
FileNotFoundError: [Errno 2] No such file or directory: '.compressed_tmp\\photo_2025-08-14_16-14-57 (16) — копия.jpg'
2025-08-14 23:46:14,982 | ERROR | Ошибка при сжатии D:\апап\photo_2025-08-14_16-14-57 (17) — копия — копия.jpg: [Errno 2] No such file or directory: '.compressed_tmp\\photo_2025-08-14_16-14-57 (17) — копия — копия.jpg'
Traceback (most recent call last):
  File "C:\Programms\JABot\upload_bot.py", line 55, in compress_image
    img.save(dst, format="JPEG", optimize=True, quality=75, progressive=True)
    ~~~~~~~~^^^^^^^^^^^^^^^^^^^^^^^^^^^^^^^^^^^^^^^^^^^^^^^^^^^^^^^^^^^^^^^^^
  File "C:\Programms\JABot\.venv\Lib\site-packages\PIL\Image.py", line 2583, in save
    fp = builtins.open(filename, "w+b")
FileNotFoundError: [Errno 2] No such file or directory: '.compressed_tmp\\photo_2025-08-14_16-14-57 (17) — копия — копия.jpg'
2025-08-14 23:46:15,001 | ERROR | Ошибка при сжатии D:\апап\photo_2025-08-14_16-14-57 (17) — копия.jpg: [Errno 2] No such file or directory: '.compressed_tmp\\photo_2025-08-14_16-14-57 (17) — копия.jpg'
Traceback (most recent call last):
  File "C:\Programms\JABot\upload_bot.py", line 55, in compress_image
    img.save(dst, format="JPEG", optimize=True, quality=75, progressive=True)
    ~~~~~~~~^^^^^^^^^^^^^^^^^^^^^^^^^^^^^^^^^^^^^^^^^^^^^^^^^^^^^^^^^^^^^^^^^
  File "C:\Programms\JABot\.venv\Lib\site-packages\PIL\Image.py", line 2583, in save
    fp = builtins.open(filename, "w+b")
FileNotFoundError: [Errno 2] No such file or directory: '.compressed_tmp\\photo_2025-08-14_16-14-57 (17) — копия.jpg'
2025-08-14 23:46:15,009 | ERROR | Ошибка при сжатии D:\апап\photo_2025-08-14_16-14-57 (18) — копия — копия.jpg: [Errno 2] No such file or directory: '.compressed_tmp\\photo_2025-08-14_16-14-57 (18) — копия — копия.jpg'
Traceback (most recent call last):
  File "C:\Programms\JABot\upload_bot.py", line 55, in compress_image
    img.save(dst, format="JPEG", optimize=True, quality=75, progressive=True)
    ~~~~~~~~^^^^^^^^^^^^^^^^^^^^^^^^^^^^^^^^^^^^^^^^^^^^^^^^^^^^^^^^^^^^^^^^^
  File "C:\Programms\JABot\.venv\Lib\site-packages\PIL\Image.py", line 2583, in save
    fp = builtins.open(filename, "w+b")
FileNotFoundError: [Errno 2] No such file or directory: '.compressed_tmp\\photo_2025-08-14_16-14-57 (18) — копия — копия.jpg'
2025-08-14 23:46:15,017 | ERROR | Ошибка при сжатии D:\апап\photo_2025-08-14_16-14-57 (18) — копия.jpg: [Errno 2] No such file or directory: '.compressed_tmp\\photo_2025-08-14_16-14-57 (18) — копия.jpg'
Traceback (most recent call last):
  File "C:\Programms\JABot\upload_bot.py", line 55, in compress_image
    img.save(dst, format="JPEG", optimize=True, quality=75, progressive=True)
    ~~~~~~~~^^^^^^^^^^^^^^^^^^^^^^^^^^^^^^^^^^^^^^^^^^^^^^^^^^^^^^^^^^^^^^^^^
  File "C:\Programms\JABot\.venv\Lib\site-packages\PIL\Image.py", line 2583, in save
    fp = builtins.open(filename, "w+b")
FileNotFoundError: [Errno 2] No such file or directory: '.compressed_tmp\\photo_2025-08-14_16-14-57 (18) — копия.jpg'
2025-08-14 23:46:15,036 | ERROR | Ошибка при сжатии D:\апап\photo_2025-08-14_16-14-57 (19) — копия — копия.jpg: [Errno 2] No such file or directory: '.compressed_tmp\\photo_2025-08-14_16-14-57 (19) — копия — копия.jpg'
Traceback (most recent call last):
  File "C:\Programms\JABot\upload_bot.py", line 55, in compress_image
    img.save(dst, format="JPEG", optimize=True, quality=75, progressive=True)
    ~~~~~~~~^^^^^^^^^^^^^^^^^^^^^^^^^^^^^^^^^^^^^^^^^^^^^^^^^^^^^^^^^^^^^^^^^
  File "C:\Programms\JABot\.venv\Lib\site-packages\PIL\Image.py", line 2583, in save
    fp = builtins.open(filename, "w+b")
FileNotFoundError: [Errno 2] No such file or directory: '.compressed_tmp\\photo_2025-08-14_16-14-57 (19) — копия — копия.jpg'
2025-08-14 23:46:15,054 | ERROR | Ошибка при сжатии D:\апап\photo_2025-08-14_16-14-57 (19) — копия.jpg: [Errno 2] No such file or directory: '.compressed_tmp\\photo_2025-08-14_16-14-57 (19) — копия.jpg'
Traceback (most recent call last):
  File "C:\Programms\JABot\upload_bot.py", line 55, in compress_image
    img.save(dst, format="JPEG", optimize=True, quality=75, progressive=True)
    ~~~~~~~~^^^^^^^^^^^^^^^^^^^^^^^^^^^^^^^^^^^^^^^^^^^^^^^^^^^^^^^^^^^^^^^^^
  File "C:\Programms\JABot\.venv\Lib\site-packages\PIL\Image.py", line 2583, in save
    fp = builtins.open(filename, "w+b")
FileNotFoundError: [Errno 2] No such file or directory: '.compressed_tmp\\photo_2025-08-14_16-14-57 (19) — копия.jpg'
2025-08-14 23:46:15,080 | ERROR | Ошибка при сжатии D:\апап\photo_2025-08-14_16-14-57 — копия.jpg: [Errno 2] No such file or directory: '.compressed_tmp\\photo_2025-08-14_16-14-57 — копия.jpg'
Traceback (most recent call last):
  File "C:\Programms\JABot\upload_bot.py", line 55, in compress_image
    img.save(dst, format="JPEG", optimize=True, quality=75, progressive=True)
    ~~~~~~~~^^^^^^^^^^^^^^^^^^^^^^^^^^^^^^^^^^^^^^^^^^^^^^^^^^^^^^^^^^^^^^^^^
  File "C:\Programms\JABot\.venv\Lib\site-packages\PIL\Image.py", line 2583, in save
    fp = builtins.open(filename, "w+b")
FileNotFoundError: [Errno 2] No such file or directory: '.compressed_tmp\\photo_2025-08-14_16-14-57 — копия.jpg'
2025-08-14 23:46:15,107 | ERROR | Ошибка при сжатии D:\апап\photo_2025-08-14_16-14-57.jpg: [Errno 2] No such file or directory: '.compressed_tmp\\photo_2025-08-14_16-14-57.jpg'
Traceback (most recent call last):
  File "C:\Programms\JABot\upload_bot.py", line 55, in compress_image
    img.save(dst, format="JPEG", optimize=True, quality=75, progressive=True)
    ~~~~~~~~^^^^^^^^^^^^^^^^^^^^^^^^^^^^^^^^^^^^^^^^^^^^^^^^^^^^^^^^^^^^^^^^^
  File "C:\Programms\JABot\.venv\Lib\site-packages\PIL\Image.py", line 2583, in save
    fp = builtins.open(filename, "w+b")
FileNotFoundError: [Errno 2] No such file or directory: '.compressed_tmp\\photo_2025-08-14_16-14-57.jpg'
2025-08-14 23:46:15,126 | ERROR | Ошибка при сжатии D:\апап\с — копия.jpg: [Errno 2] No such file or directory: '.compressed_tmp\\с — копия.jpg'
Traceback (most recent call last):
  File "C:\Programms\JABot\upload_bot.py", line 55, in compress_image
    img.save(dst, format="JPEG", optimize=True, quality=75, progressive=True)
    ~~~~~~~~^^^^^^^^^^^^^^^^^^^^^^^^^^^^^^^^^^^^^^^^^^^^^^^^^^^^^^^^^^^^^^^^^
  File "C:\Programms\JABot\.venv\Lib\site-packages\PIL\Image.py", line 2583, in save
    fp = builtins.open(filename, "w+b")
FileNotFoundError: [Errno 2] No such file or directory: '.compressed_tmp\\с — копия.jpg'
2025-08-14 23:46:15,146 | ERROR | Ошибка при сжатии D:\апап\с.jpg: [Errno 2] No such file or directory: '.compressed_tmp\\с.jpg'
Traceback (most recent call last):
  File "C:\Programms\JABot\upload_bot.py", line 55, in compress_image
    img.save(dst, format="JPEG", optimize=True, quality=75, progressive=True)
    ~~~~~~~~^^^^^^^^^^^^^^^^^^^^^^^^^^^^^^^^^^^^^^^^^^^^^^^^^^^^^^^^^^^^^^^^^
  File "C:\Programms\JABot\.venv\Lib\site-packages\PIL\Image.py", line 2583, in save
    fp = builtins.open(filename, "w+b")
FileNotFoundError: [Errno 2] No such file or directory: '.compressed_tmp\\с.jpg'
2025-08-14 23:47:39,538 | INFO | HTTP Request: POST https://api.telegram.org/bot8307958255:AAHOXk2JP0_j-lBh8Xf48lRX180J7GKRMpQ/sendMediaGroup "HTTP/1.1 200 OK"
2025-08-14 23:47:46,382 | ERROR | Не удалось подготовить файл .compressed_tmp\photo_2025-08-14_16-14-57 (19) — копия — копия.jpg: [Errno 2] No such file or directory: '.compressed_tmp\\photo_2025-08-14_16-14-57 (19) — копия — копия.jpg'
Traceback (most recent call last):
  File "C:\Programms\JABot\upload_bot.py", line 174, in process_upload
    f = open(str(p), "rb")
FileNotFoundError: [Errno 2] No such file or directory: '.compressed_tmp\\photo_2025-08-14_16-14-57 (19) — копия — копия.jpg'
2025-08-14 23:47:46,383 | ERROR | Не удалось подготовить файл .compressed_tmp\photo_2025-08-14_16-14-57 (19) — копия.jpg: [Errno 2] No such file or directory: '.compressed_tmp\\photo_2025-08-14_16-14-57 (19) — копия.jpg'
Traceback (most recent call last):
  File "C:\Programms\JABot\upload_bot.py", line 174, in process_upload
    f = open(str(p), "rb")
FileNotFoundError: [Errno 2] No such file or directory: '.compressed_tmp\\photo_2025-08-14_16-14-57 (19) — копия.jpg'
2025-08-14 23:47:46,383 | ERROR | Не удалось подготовить файл .compressed_tmp\photo_2025-08-14_16-14-57.jpg: [Errno 2] No such file or directory: '.compressed_tmp\\photo_2025-08-14_16-14-57.jpg'
Traceback (most recent call last):
  File "C:\Programms\JABot\upload_bot.py", line 174, in process_upload
    f = open(str(p), "rb")
FileNotFoundError: [Errno 2] No such file or directory: '.compressed_tmp\\photo_2025-08-14_16-14-57.jpg'
2025-08-14 23:47:46,384 | ERROR | Не удалось подготовить файл .compressed_tmp\с — копия.jpg: [Errno 2] No such file or directory: '.compressed_tmp\\с — копия.jpg'
Traceback (most recent call last):
  File "C:\Programms\JABot\upload_bot.py", line 174, in process_upload
    f = open(str(p), "rb")
FileNotFoundError: [Errno 2] No such file or directory: '.compressed_tmp\\с — копия.jpg'
2025-08-14 23:47:46,384 | ERROR | Не удалось подготовить файл .compressed_tmp\с.jpg: [Errno 2] No such file or directory: '.compressed_tmp\\с.jpg'
Traceback (most recent call last):
  File "C:\Programms\JABot\upload_bot.py", line 174, in process_upload
    f = open(str(p), "rb")
FileNotFoundError: [Errno 2] No such file or directory: '.compressed_tmp\\с.jpg'
